Workbook

Sheet Active subscribers
A1: customer | B1: lat | C1: lon | D1: address | E1: city | F1: state | G1: zip | H1: download | I1: upload | J1: voip_lines_quantity | K1: business_customer | L1: technology
A2: 1668921 | B2: =VLOOKUP(A2,'Subscribers Address'!A:G,6, FALSE) -> 40.36134 | C2: =VLOOKUP(A2,'Subscribers Address'!A:G,7, FALSE) -> -78.727006 | D2: 1735 Frankstown Rd | E2: Summermill | F2: PA | G2: 15958 | H2: 13 | I2: 8 | J2: 0 | K2: 0 | L2: wireless_unlicensed
A3: 1668873 | B3: =VLOOKUP(A3,'Subscribers Address'!A:G,6, FALSE) -> 40.440965 | C3: =VLOOKUP(A3,'Subscribers Address'!A:G,7, FALSE) -> -79.097709 | D3: 230 Rumble Road | E3: New Florence | F3: PA | G3: 15944 | H3: 45 | I3: 20 | J3: 0 | K3: 0 | L3: wireless_unlicensed
A4: 1669484 | B4: =VLOOKUP(A4,'Subscribers Address'!A:G,6, FALSE) -> 40.479001 | C4: =VLOOKUP(A4,'Subscribers Address'!A:G,7, FALSE) -> -79.215064 | D4: 1371 McConnell Rd | E4: Blairsville | F4: PA | G4: 15717 | H4: 57 | I4: 20 | J4: 0 | K4: 0 | L4: wireless_unlicensed
A5: 1669855 | B5: =VLOOKUP(A5,'Subscribers Address'!A:G,6, FALSE) -> 40.59571 | C5: =VLOOKUP(A5,'Subscribers Address'!A:G,7, FALSE) -> -78.569771 | D5: 1199 Schoolhouse Drive | E5: Dysart | F5: PA | G5: 16636 | H5: 110 | I5: 25 | J5: 0 | K5: 0 | L5: wireless_unlicensed
A6: 2452198 | B6: =VLOOKUP(A6,'Subscribers Address'!A:G,6, FALSE) -> 40.527242 | C6: =VLOOKUP(A6,'Subscribers Address'!A:G,7, FALSE) -> -78.404417 | D6: 401 22nd Avenue | E6: Altoona | F6: PA | G6: 16601 | H6: 50 | I6: 20 | J6: 0 | K6: 0 | L6: wireless_unlicensed
A7: 1668784 | B7: =VLOOKUP(A7,'Subscribers Address'!A:G,6, FALSE) -> 40.495677 | C7: =VLOOKUP(A7,'Subscribers Address'!A:G,7, FALSE) -> -78.736104 | D7: 116 Colver Rd | E7: Ebensburg | F7: PA | G7: 15931 | H7: 57 | I7: 20 | J7: 0 | K7: 0 | L7: wireless_unlicensed
A8: 2166138 | B8: =VLOOKUP(A8,'Subscribers Address'!A:G,6, FALSE) -> 40.529485 | C8: =VLOOKUP(A8,'Subscribers Address'!A:G,7, FALSE) -> -78.665161 | D8: 772 Stock Road | E8: Loretto | F8: PA | G8: 15940 | H8: 13 | I8: 8 | J8: 0 | K8: 0 | L8: wireless_unlicensed
A9: 1669154 | B9: =VLOOKUP(A9,'Subscribers Address'!A:G,6, FALSE) -> 40.137739 | C9: =VLOOKUP(A9,'Subscribers Address'!A:G,7, FALSE) -> -78.835721 | D9: 330 Miller Run Road | E9: Hooversville | F9: PA | G9: 15936 | H9: 13 | I9: 8 | J9: 0 | K9: 0 | L9: wireless_unlicensed
A10: 1668851 | B10: =VLOOKUP(A10,'Subscribers Address'!A:G,6, FALSE) -> 40.877792 | C10: =VLOOKUP(A10,'Subscribers Address'!A:G,7, FALSE) -> -78.34393 | D10: 760 Red Schoolhouse Road | E10: Osceola Mills | F10: PA | G10: 16666 | H10: 13 | I10: 8 | J10: 0 | K10: 0 | L10: wireless_unlicensed
A11: 1669413 | B11: =VLOOKUP(A11,'Subscribers Address'!A:G,6, FALSE) -> 40.620092 | C11: =VLOOKUP(A11,'Subscribers Address'!A:G,7, FALSE) -> -78.563011 | D11: 1176 St Augustine Rd | E11: Patton | F11: PA | G11: 16668 | H11: 30 | I11: 15 | J11: 1 | K11: 0 | L11: wireless_unlicensed
A12: 1670470 | B12: =VLOOKUP(A12,'Subscribers Address'!A:G,6, FALSE) -> 40.530643 | C12: =VLOOKUP(A12,'Subscribers Address'!A:G,7, FALSE) -> -78.619377 | D12: 371 Sharpe Rd | E12: Loretto | F12: PA | G12: 15940 | H12: 110 | I12: 110 | J12: 0 | K12: 0 | L12: Fiber
A13: 1875566 | B13: =VLOOKUP(A13,'Subscribers Address'!A:G,6, FALSE) -> 40.649737 | C13: =VLOOKUP(A13,'Subscribers Address'!A:G,7, FALSE) -> -78.80476 | D13: 426 Farrell Road | E13: Marsteller | F13: PA | G13: 15760 | H13: 30 | I13: 15 | J13: 0 | K13: 0 | L13: wireless_unlicensed
... A90: 1670450 | B90: =VLOOKUP(A90,'Subscribers Address'!A:G,6, FALSE) -> 40.496273 | C90: =VLOOKUP(A90,'Subscribers Address'!A:G,7, FALSE) -> -78.765963 | D90: 120 Sanborn Lane | E90: Ebensburg | F90: PA | G90: 15931 | H90: 600 | I90: 600 | J90: 0 | K90: 1 | L90: wireless_unlicensed
A91: 1768186 | B91: 40.46051 | C91: -78.76031 | D91: 388 Industrial Park Road | E91: Ebensburg | F91: PA | G91: 15931 | H91: 57 | I91: 20 | J91: 0 | K91: 0 | L91: wireless_unlicensed
A92: 1768131 | B92: =VLOOKUP(A92,'Subscribers Address'!A:G,6, FALSE) -> 40.431706 | C92: =VLOOKUP(A92,'Subscribers Address'!A:G,7, FALSE) -> -78.746627 | D92: 259 Charlies Road | E92: Summerhill | F92: PA | G92: 15958 | H92: 57 | I92: 20 | J92: 1 | K92: 0 | L92: wireless_unlicensed
A93: 2029903 | B93: =VLOOKUP(A93,'Subscribers Address'!A:G,6, FALSE) -> 40.020027 | C93: =VLOOKUP(A93,'Subscribers Address'!A:G,7, FALSE) -> -78.954831 | D93: 110 Petersburg Drive | E93: Friedens | F93: PA | G93: 15541 | H93: 30 | I93: 15 | J93: 0 | K93: 0 | L93: wireless_unlicensed
A94: 2220197 | B94: =VLOOKUP(A94,'Subscribers Address'!A:G,6, FALSE) -> 40.527381 | C94: =VLOOKUP(A94,'Subscribers Address'!A:G,7, FALSE) -> -78.601765 | D94: 706 Lincoln Road | E94: Loretto | F94: PA | G94: 15940 | H94: 110 | I94: 110 | J94: 0 | K94: 0 | L94: Fiber
A95: 1773644 | B95: =VLOOKUP(A95,'Subscribers Address'!A:G,6, FALSE) -> 40.604135 | C95: =VLOOKUP(A95,'Subscribers Address'!A:G,7, FALSE) -> -78.784182 | D95: 643 Ridge Rd | E95: Nicktown | F95: PA | G95: 15762 | H95: 45 | I95: 20 | J95: 0 | K95: 0 | L95: wireless_unlicensed
A96: 1670103 | B96: =VLOOKUP(A96,'Subscribers Address'!A:G,6, FALSE) -> 40.60411 | C96: =VLOOKUP(A96,'Subscribers Address'!A:G,7, FALSE) -> -78.834746 | D96: 184 Log Road | E96: Nicktown | F96: PA | G96: 15762 | H96: 57 | I96: 20 | J96: 0 | K96: 0 | L96: wireless_unlicensed
A97: 1898662 | B97: =VLOOKUP(A97,'Subscribers Address'!A:G,6, FALSE) -> 40.500635 | C97: =VLOOKUP(A97,'Subscribers Address'!A:G,7, FALSE) -> -78.59572 | D97: 676 Iceplant Road | E97: Gallitzin | F97: PA | G97: 16641 | H97: 45 | I97: 20 | J97: 0 | K97: 0 | L97: wireless_unlicensed
A98: 1678860 | B98: =VLOOKUP(A98,'Subscribers Address'!A:G,6, FALSE) -> 40.394389 | C98: =VLOOKUP(A98,'Subscribers Address'!A:G,7, FALSE) -> -78.770285 | D98: 252 Knipple Rd | E98: Mineral Point | F98: PA | G98: 15942 | H98: 13 | I98: 8 | J98: 0 | K98: 0 | L98: wireless_unlicensed
A99: 1871651 | B99: =VLOOKUP(A99,'Subscribers Address'!A:G,6, FALSE) -> 40.705764 | C99: =VLOOKUP(A99,'Subscribers Address'!A:G,7, FALSE) -> -78.724171 | D99: 787 Carpinello Road | E99: Hastings | F99: PA | G99: 16646 | H99: 30 | I99: 15 | J99: 0 | K99: 0 | L99: wireless_unlicensed
A100: 1668626 | B100: =VLOOKUP(A100,'Subscribers Address'!A:G,6, FALSE) -> 40.574827 | C100: =VLOOKUP(A100,'Subscribers Address'!A:G,7, FALSE) -> -78.790515 | D100: 2251 Lute Rd | E100: Ebensburg | F100: PA | G100: 15931 | H100: 45 | I100: 20 | J100: 0 | K100: 0 | L100: wireless_unlicensed
A101: 1668664 | B101: =VLOOKUP(A101,'Subscribers Address'!A:G,6, FALSE) -> 40.356046 | C101: =VLOOKUP(A101,'Subscribers Address'!A:G,7, FALSE) -> -78.747531 | D101: 650 Betz Rd | E101: Sidman | F101: PA | G101: 15955 | H101: 30 | I101: 15 | J101: 0 | K101: 0 | L101: wireless_unlicensed
A102: 2031259 | B102: =VLOOKUP(A102,'Subscribers Address'!A:G,6, FALSE) -> 40.695802 | C102: =VLOOKUP(A102,'Subscribers Address'!A:G,7, FALSE) -> -78.616194 | D102: 2189 Saint Lawrence Road | E102: Patton | F102: PA | G102: 16668 | H102: 57 | I102: 20 | J102: 0 | K102: 0 | L102: wireless_unlicensed
A103: 1669566 | B103: =VLOOKUP(A103,'Subscribers Address'!A:G,6, FALSE) -> 40.62091 | C103: =VLOOKUP(A103,'Subscribers Address'!A:G,7, FALSE) -> -75.448174 | D103: 813 North Fenwick Street | E103: Allentown | F103: PA | G103: 18109 | H103: 10 | I103: 25 | J103: 0 | K103: 0 | L103: wireless_unlicensed
... A107: 1669996 | B107: =VLOOKUP(A107,'Subscribers Address'!A:G,6, FALSE) -> 40.62722 | C107: =VLOOKUP(A107,'Subscribers Address'!A:G,7, FALSE) -> -78.555298 | D107: 1446 St Augustine Road | E107: Dysart | F107: PA | G107: 16636 | H107: 13 | I107: 8 | J107: 0 | K107: 0 | L107: wireless_unlicensed
A108: 1668848 | B108: 40.507105 | C108: -78.40755 | D108: 2035 Broad Ave | E108: Altoona | F108: PA | G108: 16601 | H108: 13 | I108: 8 | J108: 0 | K108: 0 | L108: wireless_unlicensed
A109: 1668849 | B109: 40.482915 | C109: -78.399747 | D109: 3515 Pleasant Valley Blvd | E109: Altoona | F109: PA | G109: 16602 | H109: 57 | I109: 20 | J109: 0 | K109: 0 | L109: wireless_unlicensed
A110: 2344721 | B110: =VLOOKUP(A110,'Subscribers Address'!A:G,6, FALSE) -> 40.610519 | C110: =VLOOKUP(A110,'Subscribers Address'!A:G,7, FALSE) -> -78.667109 | D110: 855 Sr4015 | E110: Patton | F110: PA | G110: 16668 | H110: 57 | I110: 20 | J110: 0 | K110: 0 | L110: wireless_unlicensed
A111: 1668618 | B111: =VLOOKUP(A111,'Subscribers Address'!A:G,6, FALSE) -> 40.410865 | C111: =VLOOKUP(A111,'Subscribers Address'!A:G,7, FALSE) -> -78.769336 | D111: 361 Tower Road | E111: Summerhill | F111: PA | G111: 15958 | H111: 13 | I111: 8 | J111: 0 | K111: 0 | L111: wireless_unlicensed
A112: 1668975 | B112: =VLOOKUP(A112,'Subscribers Address'!A:G,6, FALSE) -> 40.406683 | C112: =VLOOKUP(A112,'Subscribers Address'!A:G,7, FALSE) -> -78.908991 | D112: 255 WEEPING WILLOW LN | E112: JOHNSTOWN | F112: PA | G112: 15906 | H112: 13 | I112: 8 | J112: 0 | K112: 0 | L112: wireless_unlicensed
A113: 1669040 | B113: =VLOOKUP(A113,'Subscribers Address'!A:G,6, FALSE) -> 40.590372 | C113: =VLOOKUP(A113,'Subscribers Address'!A:G,7, FALSE) -> -78.673864 | D113: 653 Feighner Rd | E113: Carrolltown | F113: PA | G113: 15722 | H113: 110 | I113: 110 | J113: 0 | K113: 0 | L113: Fiber
A114: 1670028 | B114: =VLOOKUP(A114,'Subscribers Address'!A:G,6, FALSE) -> 40.137734 | C114: =VLOOKUP(A114,'Subscribers Address'!A:G,7, FALSE) -> -78.856821 | D114: 344 School Road | E114: Hooversville | F114: PA | G114: 15936 | H114: 30 | I114: 15 | J114: 0 | K114: 0 | L114: wireless_unlicensed
A115: 1670191 | B115: =VLOOKUP(A115,'Subscribers Address'!A:G,6, FALSE) -> 40.63249 | C115: =VLOOKUP(A115,'Subscribers Address'!A:G,7, FALSE) -> -78.603129 | D115: 104 Warefield Ln | E115: Patton | F115: PA | G115: 16668 | H115: 30 | I115: 15 | J115: 0 | K115: 0 | L115: wireless_unlicensed
A116: 1670300 | B116: =VLOOKUP(A116,'Subscribers Address'!A:G,6, FALSE) -> 40.583591 | C116: =VLOOKUP(A116,'Subscribers Address'!A:G,7, FALSE) -> -78.75954 | D116: 174 Zeke Ln | E116: Carrolltown | F116: PA | G116: 15722 | H116: 13 | I116: 8 | J116: 0 | K116: 0 | L116: wireless_unlicensed
A117: 1689885 | B117: =VLOOKUP(A117,'Subscribers Address'!A:G,6, FALSE) -> 40.165256 | C117: =VLOOKUP(A117,'Subscribers Address'!A:G,7, FALSE) -> -78.869004 | D117: 1961 Ridge Road | E117: Hooversville | F117: PA | G117: 15936 | H117: 13 | I117: 8 | J117: 0 | K117: 0 | L117: wireless_unlicensed
A118: 1765680 | B118: =VLOOKUP(A118,'Subscribers Address'!A:G,6, FALSE) -> 40.467896 | C118: =VLOOKUP(A118,'Subscribers Address'!A:G,7, FALSE) -> -78.631651 | D118: 151 Criste Road | E118: Loretto | F118: PA | G118: 15940 | H118: 13 | I118: 8 | J118: 0 | K118: 0 | L118: wireless_unlicensed
A119: 1832076 | B119: =VLOOKUP(A119,'Subscribers Address'!A:G,6, FALSE) -> 40.491365 | C119: =VLOOKUP(A119,'Subscribers Address'!A:G,7, FALSE) -> -78.96168 | D119: 2854 Barkley Church Rd | E119: Vintondale | F119: PA | G119: 15961 | H119: 30 | I119: 15 | J119: 0 | K119: 0 | L119: wireless_unlicensed
...

Sheet Customer speedlimit
A1: Customer ID | B1: Package Name | C1: Service Name | D1: Down Speed | E1: Up Speed
A2: 1668594 | B2: 10Mb Residential | C2: Wireless | D2: 13mbps | E2: 8mbps
A3: 1668598 | B3: 10Mb Residential | C3: Wireless | D3: 30mbps | E3: 12mbps
A4: 1668603 | B4: 25Mb Residential | C4: Wireless | D4: 30mbps | E4: 15mbps
A5: 1668604 | B5: 25Mb Residential | C5: Wireless | D5: 30mbps | E5: 15mbps
A6: 1668608 | B6: 10Mb Residential | C6: Wireless | D6: 13mbps | E6: 8mbps
A7: 1668611 | B7: 25Mb Residential | C7: Wireless | D7: 30mbps | E7: 15mbps
A8: 1668615 | B8: 25Mb Residential | C8: Wireless | D8: 30mbps | E8: 15mbps
A9: 1668618 | B9: 10Mb Residential | C9: Wireless | D9: 13mbps | E9: 8mbps
A10: 1668625 | B10: 50Mb Residential | C10: Wireless | D10: 57mbps | E10: 20mbps
A11: 1668626 | B11: 40Mb Residential | C11: Wireless | D11: 45mbps | E11: 20mbps
A12: 1668641 | B12: 25Mb Residential | C12: Wireless | D12: 30mbps | E12: 15mbps
A13: 1668643 | B13: 25Mb Residential | C13: Wireless | D13: 30mbps | E13: 15mbps
... A1924: 2567810 | B1924: 50Mb Residential | C1924: Wireless | D1924: 57mbps | E1924: 20mbps
A1926: Count
A1927: 1923

Sheet Package Information
A1: Name | B1: Description | C1: Services | D1: Includes | E1: Internet Service Label | F1: Package Type | G1: Internet Service Download Speed | H1: Internet Service Upload Speed
A2: 1 Gb Fiber Business | B2: 1 Gb Fiber Business | C2: 1Internet | D2: 1000 x 1000 | E2: Internet | F2: Business | G2: 1000mbps | H2: 1000mbps
A3: 100Mbps Fiber Business | B3: 100Mbps Fiber Business | C3: 1InternetService | D3: 100 x 100 | E3: InternetService | F3: Business | G3: 100mbps | H3: 100mbps
A4: 10Mb Business | C4: 110MbBusinessInternetService | E4: 10MbBusinessInternetService | F4: Business | G4: 13mbps | H4: 8mbps
A5: 200Mbps Fiber Business | B5: 200Mbps Fiber Business | C5: 1InternetService | D5: 200 x 200 | E5: InternetService | F5: Business | G5: 200mbps | H5: 200mbps
A6: 25Mb Business | C6: 125MbBusinessInternetService | E6: 25MbBusinessInternetService | F6: Business | G6: 30mbps | H6: 15mbps
A7: 400Mbps Fiber Business | B7: 400Mbps Fiber Business | C7: 1InternetService | D7: 400 x 400 | E7: InternetService | F7: Business | G7: 400mbps | H7: 400mbps
A8: 50Mb Metro Business | C8: 1Internet | E8: Internet | F8: Business | G8: 50mbps | H8: 10mbps
A9: 75Mb Business Dedicated Internet with Tower Support | C9: 1Internet | E9: Internet | F9: Business | G9: 75mbps | H9: 50mbps
A10: 75Mbps Metro Business | B10: 75Mbps Metro Business | C10: 1Internet | E10: Internet | F10: Business | G10: 75mbps | H10: 10mbps
A11: Tower Rent | C11: 1TowerRent | F11: Business
A12: 1 GB Fiber Residential | B12: 1 Gb Fiber Residential | C12: 1InternetService | D12: 1000 x 1000 | E12: InternetService | F12: Residential | G12: 1000mbps | H12: 1000mbps
A13: 1 GB Wave | B13: 1 GB Wave | C13: 1Internet | D13: 1 GB Wave | E13: Internet | F13: Residential | G13: 1000mbps | H13: 1000mbps
A14: 1 GB Wave Business | B14: 1 GB Wave Business | C14: 1Internet | D14: 1 GB Wave Business | E14: Internet | F14: Residential | G14: 1000mbps | H14: 1000mbps
A15: 100 Mb Fiber Internet | B15: 100 Mb Fiber Internet | C15: 1Internet | D15: 100 Mb Fiber Internet | E15: Internet | F15: Residential | G15: 110mbps | H15: 110mbps
A16: 100 Mb Fiber Internet $64.95 | B16: 100 Mb Fiber Internet $64.95 | C16: 1Internet | D16: 100 Mb Fiber Internet $64.95 | E16: Internet | F16: Residential | G16: 110mbps | H16: 110mbps
A17: 100 MB Wave | B17: 100 MB Wave | C17: 1Internet | D17: 100 MB Wave | E17: Internet | F17: Residential | G17: 110mbps | H17: 110mbps
A18: 100 MB Wave Business | B18: 100 MB Wave Business | C18: 1Internet | D18: 100 MB Wave Business | E18: Internet | F18: Residential | G18: 110mbps | H18: 110mbps
A19: 100Mb Fiber Internet* | B19: 100Mb Fiber Internet* | C19: 1Internet | D19: 100Mb Fiber Internet* | E19: Internet | F19: Residential | G19: 110mbps | H19: 20mbps
A20: 100Mb Metro Residential | C20: 1Internet | E20: Internet | F20: Residential | G20: 100mbps | H20: 20mbps
A21: 10Mb Residential | C21: 1Internet | E21: Internet | F21: Residential | G21: 13mbps | H21: 8mbps
A22: 15 Mbps Fiber Internet | B22: 15 Mbps Fiber Internet | C22: 1Internet | E22: Internet | F22: Residential | G22: 15mbps | H22: 20mbps
A23: 200 MB Wave | B23: 200 MB Wave | C23: 1Internet | D23: 200 MB Wave | E23: Internet | F23: Residential | G23: 220mbps | H23: 220mbps
A24: 200 Mb Wave Business | B24: 200 Mb Wave Business | C24: 1Internet | D24: 200 Mb Wave Business | E24: Internet | F24: Residential | G24: 220mbps | H24: 220mbps
A25: 200 Mbps Fiber Internet | B25: 200 Mbps Fiber Internet | C25: 1Internet | D25: 200 Mbps Fiber Internet | E25: Internet | F25: Residential | G25: 220mbps | H25: 220mbps
A26: 200Mb Fiber Internet* | B26: 200Mb Fiber Internet* | C26: 1Internet | D26: 200Mb Fiber Internet* | E26: Internet | F26: Residential | G26: 220mbps | H26: 40mbps
A27: 25 Mbps Fiber internet | B27: 25 Mbps Fiber Internet | C27: 1Internet | E27: Internet | F27: Residential
A28: 25 Mbps Metro Business | B28: 25 Mbps Metro Business | C28: 1Internet | E28: Internet | F28: Residential
A29: 25Mb Metro Residential | C29: 1Internet | E29: Internet | F29: Residential | G29: 25mbps | H29: 15mbps
A30: 25Mb Residential | B30: 6Mbps Internet | C30: 125MbResidentialInternetService | D30: 6Mbps Internet | E30: 25MbResidentialInternetService | F30: Residential | G30: 30mbps | H30: 15mbps
A31: 30 Mbps- Fabin | C31: 1Internet | D31: Internet Service | E31: Internet | F31: Residential
A32: 300 Mb WAN Transport | B32: 300 Mb WAN Transport | C32: 1Internet | D32: 300 Mb WAN Transport | E32: Internet | F32: Residential | G32: 350mbps | H32: 25mbps
A33: 400 MB Wave | B33: 400 MB Wave | C33: 1Internet | D33: 400 MB Wave | E33: Internet | F33: Residential | G33: 440mbps | H33: 440mbps
A34: 400 MB Wave Business | B34: 400 MB Wave Business | C34: 1Internet | D34: 400 MB Wave Business | E34: Internet | F34: Residential | G34: 440mbps | H34: 440mbps
A35: 400 Mbps Fiber Internet | B35: 400 Mbps Fiber Internet | C35: 1Internet | D35: 400 Mbps Fiber Internet | E35: Internet | F35: Residential | G35: 440mbps | H35: 440mbps
A36: 40Mb Business | C36: 1Internet | E36: Internet | F36: Residential | G36: 40mbps | H36: 10mbps
A37: 40Mb Business | C37: 140MbBusinessInternetService | E37: 40MbBusinessInternetService | F37: Residential | G37: 45mbps | H37: 20mbps
A38: 40Mb Residential | C38: 1Internet | E38: Internet | F38: Residential | G38: 45mbps | H38: 20mbps
A39: 500 MB Wave | B39: 500 MB Wave | C39: 1Internet | D39: 500 MB Wave | E39: Internet | F39: Residential | G39: 550mbps | H39: 550mbps
A40: 50Mb Business | C40: 150MbBusinessInternetService | E40: 50MbBusinessInternetService | F40: Residential | G40: 55mbps | H40: 25mbps
...

Sheet Subscribers Address
A1: Customer ID | B1: Address 1 | C1: City | D1: State | E1: Zip | F1: Latitude | G1: Longitude
A2: 1668592 | B2: 181 Japp Rd | C2: Summerhill | D2: PA | E2: 159580000 | F2: 40.37813 | G2: -78.760576
A3: 1668593 | B3: 126 Evergreen Road | C3: Wilmore | D3: PA | E3: 159620000 | F3: 40.389659 | G3: -78.719762
A4: 1668594 | B4: 503 Blue Road | C4: Salix | D4: PA | E4: 159520000 | F4: 40.310355 | G4: -78.786767
A5: 1668595 | B5: Cost Center 37316 | C5: Carmel | D5: IN | E5: 46082-1934 | F5: 39.978371 | G5: -86.118043
A6: 1668596 | B6: 445 Schoolhouse Road | C6: Johnstown | D6: PA | E6: 159040000 | F6: 40.271261 | G6: -78.830384
A7: 1668597 | B7: 3135 New Germany Road | C7: Ebensburg | D7: PA | E7: 159310000 | F7: 40.463305 | G7: -78.751252
A8: 1668598 | B8: PO Box 42 | C8: Cresson | D8: PA | E8: 166300000 | F8: 40.459794 | G8: -78.591684
A9: 1668599 | B9: 142 Almary Lane | C9: Dysart | D9: PA | E9: 166360000 | F9: 40.596734 | G9: -78.516962
A10: 1668600 | B10: 1405 Menoher Blvd | C10: Johnstown | D10: PA | E10: 159050000 | F10: 40.31572 | G10: -78.950773
A11: 1668601 | B11: 116 Pioneer Lake Trail | C11: Cherry Tree | D11: PA | E11: 157240000 | F11: 40.73568 | G11: -78.859282
A12: 1668602 | B12: 1625 Liberty Street | C12: Ashville | D12: PA | E12: 166130000 | F12: 40.559265 | G12: -78.547563
A13: 1668603 | B13: 147 Adams Ln | C13: Dysart | D13: PA | E13: 166360000 | F13: 40.606096 | G13: -78.575413
A14: 1668604 | B14: 209 Adams Ln | C14: Dysart | D14: PA | E14: 16636 | F14: 40.605445 | G14: -78.578867
A15: 1668605 | B15: 300 Laurel Avenie | C15: Cresson | D15: PA | E15: 166300000 | F15: 40.461584 | G15: -78.58813
A16: 1668607 | B16: 1749 Lyter Drive | C16: Johnstown | D16: PA | E16: 159050000 | F16: 40.321498 | G16: -78.956408
A17: 1668608 | B17: 417 VFW Road | C17: Carrolltown | D17: PA | E17: 157220271 | F17: 40.566477 | G17: -78.692855
... A90: 1668684 | B90: 570 Benshoff Road | C90: Summerhill | D90: PA | E90: 159580000 | F90: 40.416176 | G90: -78.775087
A91: 1668685 | B91: 138 Elm Street | C91: Fallentimber | D91: PA | E91: 16639-6208 | F91: 40.650398 | G91: -78.51119
A92: 1668686 | B92: 521 Summit St | C92: Gallitzin | D92: PA | E92: 166410000 | F92: 40.486342 | G92: -78.548177
A93: 1668687 | B93: 5239 Ridge Road | C93: Westover | D93: PA | E93: 16692 | F93: 40.778443 | G93: -78.726436
A94: 1668688 | B94: 1186 Jefferson St | C94: Loretto | D94: PA | E94: 159400000 | F94: 40.575891 | G94: -78.60844
A95: 1668689 | B95: 534 Berkey Road | C95: Bo | D95: PA | E95: 155310000 | F95: 32.83921 | G95: -97.115306
A96: 1668690 | B96: 905 Wess Rd | C96: Mineral Point | D96: PA | E96: 159420000 | F96: 40.406037 | G96: -78.780357
A97: 1668691 | B97: 156 Shimko Ln | C97: Nicktown | D97: PA | E97: 157620000 | F97: 40.612867 | G97: -78.811332
A98: 1668692 | B98: 217 Miller Rd | C98: Ebensburg | D98: PA | E98: 159310000 | F98: 40.559068 | G98: -78.735057
A99: 1668693 | B99: 172 Poole Lane | C99: Ebensburg | D99: PA | E99: 159310000 | F99: 40.575453 | G99: -78.689442
A100: 1668694 | B100: 605 Church Hill | C100: Portage | D100: PA | E100: 159460000 | F100: 40.397188 | G100: -78.698946
A101: 1668695 | B101: 594 George Lane | C101: Seward | D101: PA | E101: 159540000 | F101: 40.444795 | G101: -78.994864
A102: 1668696 | B102: 889 Wess Rd | C102: Mineral Point | D102: PA | E102: 159420000 | F102: 40.405277 | G102: -78.780387
A103: 1668697 | B103: 841 Munster Road | C103: Portage | D103: PA | E103: 159460000 | F103: 40.415985 | G103: -78.677398
... A191: 1668786 | B191: 1501 Swigle Mountain Rd | C191: Mineral Point | D191: PA | E191: 15942 | F191: 40.407696 | G191: -78.805513
A192: 1668787 | B192: 873 Wess Road | C192: Mineral Point | D192: PA | E192: 15942-5231 | F192: 40.404735 | G192: -78.780455
A193: 1668788 | B193: 5596 Camerons Road | C193: Homer City | D193: PA | E193: 157480000 | F193: 40.530572 | G193: -78.942452
A194: 1668789 | B194: 117 Alba Drive | C194: Lilly | D194: PA | E194: 159380000 | F194: 40.453185 | G194: -78.588138
A195: 1668791 | B195: 712 Gates Road | C195: Fallentimber | D195: PA | E195: 16639 | F195: 40.639523 | G195: -78.512197
A196: 1668792 | B196: Lot 106 | C196: Fallentimber | D196: PA | E196: 166390000 | F196: 40.686731 | G196: -78.499187
A197: 1668793 | B197: 3082 Colonel Drake Highway | C197: Chest Springs | D197: PA | E197: 166240000 | F197: 40.581348 | G197: -78.606862
A198: 1668794 | B198: 2798 Menoher Blvd. | C198: Johnstown | D198: PA | E198: 15905 | F198: 40.308453 | G198: -78.985596
A199: 1668795 | B199: 804 Thompson Road | C199: Blairsville | D199: PA | E199: 157170000 | F199: 40.486218 | G199: -79.240279
...
